<?xml version="1.0" encoding="UTF-8"?>
<testng-results skipped="0" failed="1" total="1" passed="0">
  <reporter-output>
  </reporter-output>
  <suite name="FaieldTestSuite" duration-ms="7" started-at="2018-05-20T19:20:14Z" finished-at="2018-05-20T19:20:14Z">
    <groups>
    </groups>
    <test name="FailedTestCases" duration-ms="7" started-at="2018-05-20T19:20:14Z" finished-at="2018-05-20T19:20:14Z">
      <class name="Testcases.Testcase2">
        <test-method status="FAIL" signature="printTestCaseName2()[pri:0, instance:Testcases.Testcase2@4b53f538]" name="printTestCaseName2" duration-ms="0" started-at="2018-05-20T15:20:14Z" finished-at="2018-05-20T15:20:14Z">
          <exception class="java.lang.AssertionError">
            <message>
              <![CDATA[expected [true] but found [false]]]>
            </message>
            <full-stacktrace>
              <![CDATA[java.lang.AssertionError: expected [true] but found [false]
	at org.testng.Assert.fail(Assert.java:94)
	at org.testng.Assert.failNotEquals(Assert.java:513)
	at org.testng.Assert.assertEqualsImpl(Assert.java:135)
	at org.testng.Assert.assertEquals(Assert.java:116)
	at org.testng.Assert.assertEquals(Assert.java:305)
	at org.testng.Assert.assertEquals(Assert.java:315)
	at Testcases.Testcase2.printTestCaseName2(Testcase2.java:29)
	at sun.reflect.NativeMethodAccessorImpl.invoke0(Native Method)
	at sun.reflect.NativeMethodAccessorImpl.invoke(NativeMethodAccessorImpl.java:62)
	at sun.reflect.DelegatingMethodAccessorImpl.invoke(DelegatingMethodAccessorImpl.java:43)
	at java.lang.reflect.Method.invoke(Method.java:498)
	at org.testng.internal.MethodInvocationHelper.invokeMethod(MethodInvocationHelper.java:100)
	at org.testng.internal.Invoker.invokeMethod(Invoker.java:646)
	at org.testng.internal.Invoker.invokeTestMethod(Invoker.java:811)
	at org.testng.internal.Invoker.invokeTestMethods(Invoker.java:1137)
	at org.testng.internal.TestMethodWorker.invokeTestMethods(TestMethodWorker.java:129)
	at org.testng.internal.TestMethodWorker.run(TestMethodWorker.java:112)
	at org.testng.TestRunner.privateRun(TestRunner.java:753)
	at org.testng.TestRunner.run(TestRunner.java:607)
	at org.testng.SuiteRunner.runTest(SuiteRunner.java:368)
	at org.testng.SuiteRunner.runSequentially(SuiteRunner.java:363)
	at org.testng.SuiteRunner.privateRun(SuiteRunner.java:321)
	at org.testng.SuiteRunner.run(SuiteRunner.java:270)
	at org.testng.SuiteRunnerWorker.runSuite(SuiteRunnerWorker.java:52)
	at org.testng.SuiteRunnerWorker.run(SuiteRunnerWorker.java:86)
	at org.testng.TestNG.runSuitesSequentially(TestNG.java:1284)
	at org.testng.TestNG.runSuitesLocally(TestNG.java:1209)
	at org.testng.TestNG.runSuites(TestNG.java:1124)
	at org.testng.TestNG.run(TestNG.java:1096)
	at Testcases.GenerateTestNGXML.rerunfailedtestcase(GenerateTestNGXML.java:186)
	at Testcases.Testrunner.main(Testrunner.java:37)
]]>
            </full-stacktrace>
          </exception> <!-- java.lang.AssertionError -->
          <reporter-output>
          </reporter-output>
        </test-method> <!-- printTestCaseName2 -->
        <test-method status="PASS" signature="afterMethod(org.testng.ITestResult)[pri:0, instance:Testcases.Testcase2@4b53f538]" name="afterMethod" is-config="true" duration-ms="6" started-at="2018-05-20T15:20:14Z" finished-at="2018-05-20T15:20:14Z">
          <params>
            <param index="0">
              <value>
                <![CDATA[[TestResult name=printTestCaseName2 status=FAILURE method=Testcase2.printTestCaseName2()[pri:0, instance:Testcases.Testcase2@4b53f538] output={null}]]]>
              </value>
            </param>
          </params>
          <reporter-output>
          </reporter-output>
        </test-method> <!-- afterMethod -->
      </class> <!-- Testcases.Testcase2 -->
    </test> <!-- FailedTestCases -->
  </suite> <!-- FaieldTestSuite -->
</testng-results>
